<?xml version="1.0" encoding="utf-8"?>

<robot
  name="chimuelo_description">
  <link
    name="base_link">
    <inertial>
      <origin
        xyz="-0.021674 0.0012486 0.02614"
        rpy="0 0 0" />
      <mass
        value="6.9434" />
      <inertia
        ixx="0.097544"
        ixy="-0.00014641"
        ixz="0.012133"
        iyy="0.12117"
        iyz="0.00018542"
        izz="0.1655" />
    </inertial>
    <visual>
      <origin
        xyz="0 0 0"
        rpy="0 0 0" />
      <geometry>
        <mesh
          filename="package://chimuelo/meshes/base_link.STL" />
      </geometry>
      <material
        name="">
        <color
          rgba="7529411765 2235294118 168627451 1" />
      </material>
    </visual>
    <collision>
      <origin
        xyz="0 0 0"
        rpy="0 0 0" />
      <geometry>
        <mesh
          filename="package://chimuelo/meshes/base_link.STL" />
      </geometry>
    </collision>
  </link>
  <link
    name="support_right_link">
    <inertial>
      <origin
        xyz="-0.071411 -0.042763 -0.15841"
        rpy="0 0 0" />
      <mass
        value="0.35361" />
      <inertia
        ixx="0.0028314"
        ixy="-2.621E-06"
        ixz="-9.7089E-06"
        iyy="0.0024921"
        iyz="-0.0006218"
        izz="0.00035656" />
    </inertial>
    <visual>
      <origin
        xyz="0 0 0"
        rpy="0 0 0" />
      <geometry>
        <mesh
          filename="package://chimuelo/meshes/support_right_link.STL" />
      </geometry>
      <material
        name="">
        <color
          rgba="8156862745 8274509804 831372549 1" />
      </material>
    </visual>
    <collision>
      <origin
        xyz="0 0 0"
        rpy="0 0 0" />
      <geometry>
        <mesh
          filename="package://chimuelo/meshes/support_right_link.STL" />
      </geometry>
    </collision>
  </link>
  <joint
    name="support_right_joint"
    type="fixed">
    <origin
      xyz="0.15956 -0.22452 -0.14324"
      rpy="-2.3026 0 -1.5708" />
    <parent
      link="base_link" />
    <child
      link="support_right_link" />
    <axis
      xyz="0 0 0" />
  </joint>
  <link
    name="front_right_wheel">
    <inertial>
      <origin
        xyz="-0.030145 7.2299E-06 -7.774E-07"
        rpy="0 0 0" />
      <mass
        value="0.95802" />
      <inertia
        ixx="0.0027027"
        ixy="3.8106E-07"
        ixz="-4.0985E-08"
        iyy="0.0015854"
        iyz="-3.6463E-09"
        izz="0.0015854" />
    </inertial>
    <visual>
      <origin
        xyz="0 0 0"
        rpy="0 0 0" />
      <geometry>
        <mesh
          filename="package://chimuelo/meshes/front_right_wheel.STL" />
      </geometry>
      <material
        name="">
        <color
          rgba="0.79216 0.81961 0.93333 1" />
      </material>
    </visual>
    <collision>
      <origin
        xyz="0 0 0"
        rpy="0 0 0" />
      <geometry>
        <mesh
          filename="package://chimuelo/meshes/front_right_wheel.STL" />
      </geometry>
    </collision>
  </link>
  <joint
    name="front_right_joint"
    type="continuous">
    <origin
      xyz="0 0 0"
      rpy="0 0 0" />
    <parent
      link="support_right_link" />
    <child
      link="front_right_wheel" />
    <axis
      xyz="1 0 0" />
  </joint>
  <link
    name="support_left_wheel">
    <inertial>
      <origin
        xyz="0.039589 -0.15654 0.049162"
        rpy="0 0 0" />
      <mass
        value="0.35361" />
      <inertia
        ixx="0.0028314"
        ixy="-9.5944E-06"
        ixz="3.0131E-06"
        iyy="0.00041055"
        iyz="0.00070642"
        izz="0.0024381" />
    </inertial>
    <visual>
      <origin
        xyz="0 0 0"
        rpy="0 0 0" />
      <geometry>
        <mesh
          filename="package://chimuelo/meshes/support_left_wheel.STL" />
      </geometry>
      <material
        name="">
        <color
          rgba="8156862745 8274509804 831372549 1" />
      </material>
    </visual>
    <collision>
      <origin
        xyz="0 0 0"
        rpy="0 0 0" />
      <geometry>
        <mesh
          filename="package://chimuelo/meshes/support_left_wheel.STL" />
      </geometry>
    </collision>
  </link>
  <joint
    name="support_left_joint"
    type="fixed">
    <origin
      xyz="0.15956 0.11368 -0.14324"
      rpy="-1.8418 0 1.5708" />
    <parent
      link="base_link" />
    <child
      link="support_left_wheel" />
    <axis
      xyz="0 0 0" />
  </joint>
  <link
    name="front_left_wheel">
    <inertial>
      <origin
        xyz="0.080855 -3.7512E-06 6.2293E-06"
        rpy="0 0 0" />
      <mass
        value="0.95802" />
      <inertia
        ixx="0.0027027"
        ixy="-1.9771E-07"
        ixz="3.2833E-07"
        iyy="0.0015854"
        iyz="-1.5204E-08"
        izz="0.0015854" />
    </inertial>
    <visual>
      <origin
        xyz="0 0 0"
        rpy="0 0 0" />
      <geometry>
        <mesh
          filename="package://chimuelo/meshes/front_left_wheel.STL" />
      </geometry>
      <material
        name="">
        <color
          rgba="0.79216 0.81961 0.93333 1" />
      </material>
    </visual>
    <collision>
      <origin
        xyz="0 0 0"
        rpy="0 0 0" />
      <geometry>
        <mesh
          filename="package://chimuelo/meshes/front_left_wheel.STL" />
      </geometry>
    </collision>
  </link>
  <joint
    name="front_left_joint"
    type="continuous">
    <origin
      xyz="0 0 0"
      rpy="0 0 0" />
    <parent
      link="support_left_wheel" />
    <child
      link="front_left_wheel" />
    <axis
      xyz="1 0 0" />
  </joint>
  <link
    name="rear_right_link">
    <inertial>
      <origin
        xyz="-0.013975 0.054321 9.9024E-05"
        rpy="0 0 0" />
      <mass
        value="0.053734" />
      <inertia
        ixx="2.524E-05"
        ixy="-1.6585E-06"
        ixz="9.9779E-08"
        iyy="2.9055E-05"
        iyz="2.0355E-07"
        izz="2.0458E-05" />
    </inertial>
    <visual>
      <origin
        xyz="0 0 0"
        rpy="0 0 0" />
      <geometry>
        <mesh
          filename="package://chimuelo/meshes/rear_right_link.STL" />
      </geometry>
      <material
        name="">
        <color
          rgba="0.25098 0.25098 0.25098 1" />
      </material>
    </visual>
    <collision>
      <origin
        xyz="0 0 0"
        rpy="0 0 0" />
      <geometry>
        <mesh
          filename="package://chimuelo/meshes/rear_right_link.STL" />
      </geometry>
    </collision>
  </link>
  <joint
    name="rear_right_joint1"
    type="continuous">
    <origin
      xyz="-0.12756 -0.076921 -0.14918"
      rpy="1.5688 0.13961 -0.014686" />
    <parent
      link="base_link" />
    <child
      link="rear_right_link" />
    <axis
      xyz="0 0 0" />
  </joint>
  <link
    name="rear_right_wheel">
    <inertial>
      <origin
        xyz="0.0014035 7.5454E-12 1.17E-06"
        rpy="0 0 0" />
      <mass
        value="0.2056" />
      <inertia
        ixx="0.00020145"
        ixy="-4.2403E-14"
        ixz="-5.6953E-14"
        iyy="0.00011972"
        iyz="5.3531E-16"
        izz="0.00011972" />
    </inertial>
    <visual>
      <origin
        xyz="0 0 0"
        rpy="0 0 0" />
      <geometry>
        <mesh
          filename="package://chimuelo/meshes/rear_right_wheel.STL" />
      </geometry>
      <material
        name="">
        <color
          rgba="9019600000 4941176471 1333333333 1" />
      </material>
    </visual>
    <collision>
      <origin
        xyz="0 0 0"
        rpy="0 0 0" />
      <geometry>
        <mesh
          filename="package://chimuelo/meshes/rear_right_wheel.STL" />
      </geometry>
    </collision>
  </link>
  <joint
    name="rear_right_joint2"
    type="continuous">
    <origin
      xyz="-0.03659 0.014924 -0.0015141"
      rpy="2.894 -1.5708 0" />
    <parent
      link="rear_right_link" />
    <child
      link="rear_right_wheel" />
    <axis
      xyz="0 0 0" />
  </joint>
  <link
    name="rear_left_link">
    <inertial>
      <origin
        xyz="-0.013975 0.054321 9.9024E-05"
        rpy="0 0 0" />
      <mass
        value="0.053734" />
      <inertia
        ixx="2.524E-05"
        ixy="-1.6585E-06"
        ixz="9.9779E-08"
        iyy="2.9055E-05"
        iyz="2.0355E-07"
        izz="2.0458E-05" />
    </inertial>
    <visual>
      <origin
        xyz="0 0 0"
        rpy="0 0 0" />
      <geometry>
        <mesh
          filename="package://chimuelo/meshes/rear_left_link.STL" />
      </geometry>
      <material
        name="">
        <color
          rgba="0.25098 0.25098 0.25098 1" />
      </material>
    </visual>
    <collision>
      <origin
        xyz="0 0 0"
        rpy="0 0 0" />
      <geometry>
        <mesh
          filename="package://chimuelo/meshes/rear_left_link.STL" />
      </geometry>
    </collision>
  </link>
  <joint
    name="rear_left_joint1"
    type="continuous">
    <origin
      xyz="-0.12756 0.077079 -0.14918"
      rpy="1.5688 0.13961 -0.014686" />
    <parent
      link="base_link" />
    <child
      link="rear_left_link" />
    <axis
      xyz="0 0 0" />
  </joint>
  <link
    name="rear_left_wheel">
    <inertial>
      <origin
        xyz="0.0014035 7.5453E-12 1.17E-06"
        rpy="0 0 0" />
      <mass
        value="0.2056" />
      <inertia
        ixx="0.00020145"
        ixy="-4.2403E-14"
        ixz="-5.6953E-14"
        iyy="0.00011972"
        iyz="5.3532E-16"
        izz="0.00011972" />
    </inertial>
    <visual>
      <origin
        xyz="0 0 0"
        rpy="0 0 0" />
      <geometry>
        <mesh
          filename="package://chimuelo/meshes/rear_left_wheel.STL" />
      </geometry>
      <material
        name="">
        <color
          rgba="9019600000 4941200000 1333333333 1" />
      </material>
    </visual>
    <collision>
      <origin
        xyz="0 0 0"
        rpy="0 0 0" />
      <geometry>
        <mesh
          filename="package://chimuelo/meshes/rear_left_wheel.STL" />
      </geometry>
    </collision>
  </link>
  <joint
    name="rear_left_joint2"
    type="continuous">
    <origin
      xyz="-0.03659 0.014924 -0.0015141"
      rpy="2.894 -1.5708 0" />
    <parent
      link="rear_left_link" />
    <child
      link="rear_left_wheel" />
    <axis
      xyz="0 0 0" />
  </joint>
  <link
    name="camerafront_Link">
    <inertial>
      <origin
        xyz="-0.002 4.4409E-16 0"
        rpy="0 0 0" />
      <mass
        value="0.016731" />
      <inertia
        ixx="1.6437E-05"
        ixy="-4.8473E-23"
        ixz="3.2529E-22"
        iyy="2.278E-06"
        iyz="-8.6856E-22"
        izz="1.4204E-05" />
    </inertial>
    <visual>
      <origin
        xyz="0 0 0"
        rpy="0 0 0" />
      <geometry>
        <mesh
          filename="package://chimuelo/meshes/camerafront_Link.STL" />
      </geometry>
      <material
        name="">
        <color
          rgba="0.79216 0.81961 0.93333 0.3" />
      </material>
    </visual>
    <collision>
      <origin
        xyz="0 0 0"
        rpy="0 0 0" />
      <geometry>
        <mesh
          filename="package://chimuelo/meshes/camerafront_Link.STL" />
      </geometry>
    </collision>
  </link>
  <joint
    name="camerafront_joint"
    type="fixed">
    <origin
      xyz="0.21053 7.9351E-05 0.035594"
      rpy="0 0 0" />
    <parent
      link="base_link" />
    <child
      link="camerafront_Link" />
    <axis
      xyz="0 0 0" />
  </joint>
  <link
    name="cameraback_Link">
    <inertial>
      <origin
        xyz="-0.0016341 -2.4731E-06 -0.0011538"
        rpy="0 0 0" />
      <mass
        value="0.011713" />
      <inertia
        ixx="9.0103E-06"
        ixy="-4.9082E-11"
        ixz="4.3103E-07"
        iyy="9.4862E-07"
        iyz="7.7782E-11"
        izz="8.6965E-06" />
    </inertial>
    <visual>
      <origin
        xyz="0 0 0"
        rpy="0 0 0" />
      <geometry>
        <mesh
          filename="package://chimuelo/meshes/cameraback_Link.STL" />
      </geometry>
      <material
        name="">
        <color
          rgba="0.79216 0.81961 0.93333 0.3" />
      </material>
    </visual>
    <collision>
      <origin
        xyz="0 0 0"
        rpy="0 0 0" />
      <geometry>
        <mesh
          filename="package://chimuelo/meshes/cameraback_Link.STL" />
      </geometry>
    </collision>
  </link>
  <joint
    name="cameraback_joint"
    type="fixed">
    <origin
      xyz="-0.24453 0.0020794 0.17412"
      rpy="0 -0.17323 -3.1416" />
    <parent
      link="base_link" />
    <child
      link="cameraback_Link" />
    <axis
      xyz="0 0 0" />
  </joint>
  <link
    name="lidar_Link">
    <inertial>
      <origin
        xyz="-1.8682E-06 0.000177 -0.03563"
        rpy="0 0 0" />
      <mass
        value="0.61591" />
      <inertia
        ixx="0.00069061"
        ixy="-2.0789E-10"
        ixz="-3.8206E-08"
        iyy="0.00068379"
        iyz="3.1803E-06"
        izz="0.00083915" />
    </inertial>
    <visual>
      <origin
        xyz="0 0 0"
        rpy="0 0 0" />
      <geometry>
        <mesh
          filename="package://chimuelo/meshes/lidar_Link.STL" />
      </geometry>
      <material
        name="">
        <color
          rgba="0.95294 0.99608 0.69412 1" />
      </material>
    </visual>
    <collision>
      <origin
        xyz="0 0 0"
        rpy="0 0 0" />
      <geometry>
        <mesh
          filename="package://chimuelo/meshes/lidar_Link.STL" />
      </geometry>
    </collision>
  </link>
  <joint
    name="lidar_joint"
    type="fixed">
    <origin
      xyz="0.0024523 0.0019288 0.2346"
      rpy="0 0 0" />
    <parent
      link="base_link" />
    <child
      link="lidar_Link" />
    <axis
      xyz="0 0 0" />
  </joint>
  <link
    name="sup_Link">
    <inertial>
      <origin
        xyz="0.0092271 -0.15 0.013958"
        rpy="0 0 0" />
      <mass
        value="0.43898" />
      <inertia
        ixx="0.0061052"
        ixy="-8.9571E-08"
        ixz="0.0015258"
        iyy="0.0078076"
        iyz="2.3811E-08"
        izz="0.011427" />
    </inertial>
    <visual>
      <origin
        xyz="0 0 0"
        rpy="0 0 0" />
      <geometry>
        <mesh
          filename="package://chimuelo/meshes/sup_Link.STL" />
      </geometry>
      <material
        name="">
        <color
          rgba="1 1 1 0.3" />
      </material>
    </visual>
    <collision>
      <origin
        xyz="0 0 0"
        rpy="0 0 0" />
      <geometry>
        <mesh
          filename="package://chimuelo/meshes/sup_Link.STL" />
      </geometry>
    </collision>
  </link>
  <joint
    name="sup_joint"
    type="fixed">
    <origin
      xyz="0.004191 0.15008 0.18491"
      rpy="0 0 0" />
    <parent
      link="base_link" />
    <child
      link="sup_Link" />
    <axis
      xyz="0 0 0" />
  </joint>
  <link
    name="luces_Link">
    <inertial>
      <origin
        xyz="-0.023886 -6.2177E-07 0.013779"
        rpy="0 0 0" />
      <mass
        value="0.38703" />
      <inertia
        ixx="0.00085878"
        ixy="2.2072E-09"
        ixz="5.4087E-05"
        iyy="0.0003374"
        iyz="-3.4489E-10"
        izz="0.00077205" />
    </inertial>
    <visual>
      <origin
        xyz="0 0 0"
        rpy="0 0 0" />
      <geometry>
        <mesh
          filename="package://chimuelo/meshes/luces_Link.STL" />
      </geometry>
      <material
        name="">
        <color
          rgba="9019607843 4941176471 0.13333 0.3" />
      </material>
    </visual>
    <collision>
      <origin
        xyz="0 0 0"
        rpy="0 0 0" />
      <geometry>
        <mesh
          filename="package://chimuelo/meshes/luces_Link.STL" />
      </geometry>
    </collision>
  </link>
  <joint
    name="luces_joint"
    type="fixed">
    <origin
      xyz="-0.25232 0.0020794 0.13327"
      rpy="0 0.10375 3.1416" />
    <parent
      link="base_link" />
    <child
      link="luces_Link" />
    <axis
      xyz="0 0 0" />
  </joint>
  <link
    name="tapas_Link">
    <inertial>
      <origin
        xyz="0 0 0"
        rpy="0 0 0" />
      <mass
        value="0" />
      <inertia
        ixx="0"
        ixy="0"
        ixz="0"
        iyy="0"
        iyz="0"
        izz="0" />
    </inertial>
    <visual>
      <origin
        xyz="0 0 0"
        rpy="0 0 0" />
      <geometry>
        <mesh
          filename="package://chimuelo/meshes/tapas_Link.STL" />
      </geometry>
      <material
        name="">
        <color
          rgba="1 1 1 1" />
      </material>
    </visual>
    <collision>
      <origin
        xyz="0 0 0"
        rpy="0 0 0" />
      <geometry>
        <mesh
          filename="package://chimuelo/meshes/tapas_Link.STL" />
      </geometry>
    </collision>
  </link>
  <joint
    name="tapas_joint"
    type="fixed">
    <origin
      xyz="0.21153 7.9351E-05 -0.032426"
      rpy="1.5708 0 0" />
    <parent
      link="base_link" />
    <child
      link="tapas_Link" />
    <axis
      xyz="0 0 0" />
  </joint>
  <!-- Camera Back plugin -->
  <gazebo reference="cameraback_Link">
    <sensor type="camera" name="camera_sensor">
      <update_rate>100.0</update_rate>
      <always_on>1</always_on>
      <visualize>true</visualize>

      <camera name="camera">
        <horizontal_fov>1.3962634</horizontal_fov>
        <image>
          <width>640</width>
          <height>480</height>
          <format>R8G8B8</format>
        </image>
        <clip>
          <near>0.02</near>
          <far>320</far>
        </clip>
        <distortion>
          <k1>0.0</k1>
          <k2>0.0</k2>
          <k3>0.0</k3>
          <p1>0.0</p1>
          <p2>0.0</p2>
          <center>0.5 0.5</center>
        </distortion>
      </camera>
      <plugin name="camera_controller" filename="libgazebo_ros_camera.so">
        <ros>
          <namespace>/bocbot</namespace>
          <argument>camera/image_raw:=/bocbot/camera/image</argument>
          <argument>camera/camera_info:=/bocbot/camera/image/cameraback_info</argument>
        </ros>
        <camera_name>cameraback</camera_name>
        <frame_name>cameraback_Link</frame_name>
        <hack_baseline>0.07</hack_baseline>
      </plugin>
    </sensor>
  </gazebo>
  <!-- Camera Front plugin -->
  <gazebo reference="camerafront_Link">
    <sensor type="camera" name="camera_sensor">
      <update_rate>100.0</update_rate>
      <always_on>1</always_on>
      <visualize>true</visualize>

      <camera name="camera">
        <horizontal_fov>1.3962634</horizontal_fov>
        <image>
          <width>640</width>
          <height>480</height>
          <format>R8G8B8</format>
        </image>
        <clip>
          <near>0.02</near>
          <far>320</far>
        </clip>
        <distortion>
          <k1>0.0</k1>
          <k2>0.0</k2>
          <k3>0.0</k3>
          <p1>0.0</p1>
          <p2>0.0</p2>
          <center>0.5 0.5</center>
        </distortion>
      </camera>
      <plugin name="camera_controller" filename="libgazebo_ros_camera.so">
        <ros>
          <namespace>/bocbot</namespace>
          <argument>camera/image_raw:=/bocbot/camera/image</argument>
          <argument>camera/camera_info:=/bocbot/camera/image/camerafront_info</argument>
        </ros>
        <camera_name>camerafront</camera_name>
        <frame_name>camerafront_Link</frame_name>
        <hack_baseline>0.07</hack_baseline>
      </plugin>
    </sensor>
  </gazebo>
  <!-- LiDar plugin -->
  <gazebo reference="lidar_Link">
    <sensor name="lidar" type="gpu_ray">
      <always_on>true</always_on>
      <visualize>false</visualize>
      <update_rate>5</update_rate>
      <ray>
        <scan>
          <horizontal>
            <samples>120</samples>
            <resolution>1.000000</resolution>
            <min_angle>-3.14159</min_angle>
            <max_angle>3.14159</max_angle>
          </horizontal>
          <vertical>
                <samples>120</samples>
                <resolution>1</resolution>
                <min_angle>-${15.0*3.1415926535897931/180.0}</min_angle>
                <max_angle> ${15.0*3.1415926535897931/180.0}</max_angle>
              </vertical>
        </scan>
        <range>
          <min>0.3</min>
          <max>15.0</max>
          <resolution>0.001</resolution>
        </range>
        <noise>
          <type>gaussian</type>
          <mean>0.0</mean>
          <stddev>0.01</stddev>
        </noise>
      </ray>
      <plugin name="gazebo_ros_laser_controller" filename="libgazebo_ros_velodyne_gpu_laser.so">
        
        <ros>
          <remapping>~/out:=scan</remapping>
          
        </ros>
        <output_type>sensor_msgs/LaserScan</output_type>
        <topicName>~/velodyne_points</topicName>
        <frame_name>lidar_Link</frame_name>
      </plugin>
    </sensor>
  </gazebo>
  <gazebo reference="lidar_Link">
    <mu1>0.01</mu1>
    <mu2>0.01</mu2>
    <material>Gazebo/Black</material>
  </gazebo>
  <!-- *********************** WHEEL ODOMETRY ***************************    --> 
  <gazebo>
    <plugin name="two_wheeled_robot_diff_drive" filename="libgazebo_ros_diff_drive.so">

      <update_rate>30</update_rate>
     
      <!-- wheels -->
      <left_joint>front_left_joint</left_joint>
      <right_joint>front_right_joint</right_joint>

      <!-- kinematics -->
      <wheel_separation>0.33820</wheel_separation>
      <wheel_diameter>0.15875</wheel_diameter>

      <!-- limits -->
      <max_wheel_torque>20</max_wheel_torque>
      <max_wheel_acceleration>1.0</max_wheel_acceleration>

      <!-- Receive velocity commands on this ROS topic -->
      <command_topic>cmd_vel</command_topic>

      <!-- output -->
      <!-- When false, publish no wheel odometry data to a ROS topic -->
      <publish_odom>true</publish_odom>

      <!-- When true, publish coordinate transform from odom to base_footprint -->
      <!-- I usually use the robot_localization package to publish this transform -->   
      <publish_odom_tf>false</publish_odom_tf>
    
      <!-- When true, publish coordinate transform from base_link to the wheels -->
      <!-- The robot_state_publisher package is often used to publish this transform -->   
      <publish_wheel_tf>true</publish_wheel_tf>

      <odometry_topic>odom</odometry_topic>
      <odometry_frame>odom</odometry_frame>
      <robot_base_frame>base_link</robot_base_frame>

      <odometry_source>1</odometry_source>
      <ros>
        <remapping>odom:=wheel/odometry</remapping>
      </ros>
    </plugin>
  </gazebo>

</robot>
