<?xml version="1.0" encoding="utf-8"?>
<robot
  name="chimuelo">
  <link name="base_footprint">
  </link>
  <joint name="base_joint"    type="fixed">
    <origin xyz="0 0 0.22579" rpy="0 -0.150640 0" />
    <parent link="base_footprint" />
    <child link="base_link" />
  </joint>
  <link
    name="base_link">
    <inertial>
      <origin
        xyz="-0.0216740372788278 0.00124864616977205 0.0261402435715905"
        rpy="0 0 0" />
      <mass
        value="6.94341094290304" />
      <inertia
        ixx="0.0975436464728163"
        ixy="-0.00014640763141814"
        ixz="0.0121330819883208"
        iyy="0.121165209748917"
        iyz="0.000185415935459233"
        izz="0.165495376638432" />
    </inertial>
    <visual>
      <origin
        xyz="0 0 0"
        rpy="0 0 0" />
      <geometry>
        <mesh
          filename="package://chimuelo/meshes/base_link.STL" />
      </geometry>
      <material
        name="">
        <color
          rgba="0.694117647058824 0.0980392156862745 0.0980392156862745 1" />
      </material>
    </visual>
    <collision>
      <origin
        xyz="0 0 0"
        rpy="0 0 0" />
      <geometry>
        <mesh
          filename="package://chimuelo/meshes/base_link.STL" />
      </geometry>
    </collision>
  </link>
  <link
    name="support_right_link">
    <inertial>
      <origin
        xyz="-0.0714109525601541 -0.042763316412401 -0.15840886849974"
        rpy="0 0 0" />
      <mass
        value="0.353609382798254" />
      <inertia
        ixx="0.00283139843805344"
        ixy="-2.62097196592732E-06"
        ixz="-9.70891030733253E-06"
        iyy="0.0024920617230395"
        iyz="-0.000621804484159396"
        izz="0.000356560395401477" />
    </inertial>
    <visual>
      <origin
        xyz="0 0 0"
        rpy="0 0 0" />
      <geometry>
        <mesh
          filename="package://chimuelo/meshes/support_right_link.STL" />
      </geometry>
      <material
        name="">
        <color
          rgba="0.792156862745098 0.819607843137255 0.933333333333333 1" />
      </material>
    </visual>
    <collision>
      <origin
        xyz="0 0 0"
        rpy="0 0 0" />
      <geometry>
        <mesh
          filename="package://chimuelo/meshes/support_right_link.STL" />
      </geometry>
    </collision>
  </link>
  <joint
    name="support_right_joint"
    type="fixed">
    <origin
      xyz="0.159560184718846 -0.224520648877531 -0.143241992073655"
      rpy="-2.30262522200924 0 -1.5707963267949" />
    <parent
      link="base_link" />
    <child
      link="support_right_link" />
    <axis
      xyz="0 0 0" />
  </joint>
  <link
    name="front_right_wheel">
    <inertial>
      <origin
        xyz="-0.030145497626775 7.22989820794995E-06 -7.77401324758564E-07"
        rpy="0 0 0" />
      <mass
        value="0.958024094062945" />
      <inertia
        ixx="0.00270274022435054"
        ixy="3.81064770864891E-07"
        ixz="-4.09847657707184E-08"
        iyy="0.00158540664013575"
        iyz="-3.64629548717287E-09"
        izz="0.0015853730297152" />
    </inertial>
    <visual>
      <origin
        xyz="0 0 0"
        rpy="0 0 0" />
      <geometry>
        <mesh
          filename="package://chimuelo/meshes/front_right_wheel.STL" />
      </geometry>
      <material
        name="">
        <color
          rgba="0.792156862745098 0.819607843137255 0.933333333333333 1" />
      </material>
    </visual>
    <collision>
      <origin
        xyz="0 0 0"
        rpy="0 0 0" />
      <geometry>
        <mesh
          filename="package://chimuelo/meshes/front_right_wheel.STL" />
      </geometry>
    </collision>
  </link>
  <joint
    name="front_right_joint"
    type="continuous">
    <origin
      xyz="0 0 0"
      rpy="0 0 0" />
    <parent
      link="support_right_link" />
    <child
      link="front_right_wheel" />
    <axis
      xyz="1 0 0" />
  </joint>
  <link
    name="support_left_wheel">
    <inertial>
      <origin
        xyz="0.0395890474398459 -0.156541319305258 0.0491618368261818"
        rpy="0 0 0" />
      <mass
        value="0.353609382798251" />
      <inertia
        ixx="0.00283139843805341"
        ixy="-9.59444785459561E-06"
        ixz="3.01313852443746E-06"
        iyy="0.000410550839724708"
        iyz="0.000706415256046002"
        izz="0.00243807127871625" />
    </inertial>
    <visual>
      <origin
        xyz="0 0 0"
        rpy="0 0 0" />
      <geometry>
        <mesh
          filename="package://chimuelo/meshes/support_left_wheel.STL" />
      </geometry>
      <material
        name="">
        <color
          rgba="0.792156862745098 0.819607843137255 0.933333333333333 1" />
      </material>
    </visual>
    <collision>
      <origin
        xyz="0 0 0"
        rpy="0 0 0" />
      <geometry>
        <mesh
          filename="package://chimuelo/meshes/support_left_wheel.STL" />
      </geometry>
    </collision>
  </link>
  <joint
    name="support_left_joint"
    type="fixed">
    <origin
      xyz="0.15956 0.11368 -0.14324"
      rpy="-1.8418 0 1.5708" />
    <parent
      link="base_link" />
    <child
      link="support_left_wheel" />
    <axis
      xyz="0 0 0" />
  </joint>
  <link
    name="front_left_wheel">
    <inertial>
      <origin
        xyz="0.0808545023732252 -3.75120321544076E-06 6.22930616922535E-06"
        rpy="0 0 0" />
      <mass
        value="0.958024094062945" />
      <inertia
        ixx="0.00270274022435055"
        ixy="-1.97705592432438E-07"
        ixz="3.28333076827714E-07"
        iyy="0.00158538179996911"
        iyz="-1.52036192867613E-08"
        izz="0.00158539786988184" />
    </inertial>
    <visual>
      <origin
        xyz="0 0 0"
        rpy="0 0 0" />
      <geometry>
        <mesh
          filename="package://chimuelo/meshes/front_left_wheel.STL" />
      </geometry>
      <material
        name="">
        <color
          rgba="0.792156862745098 0.819607843137255 0.933333333333333 1" />
      </material>
    </visual>
    <collision>
      <origin
        xyz="0 0 0"
        rpy="0 0 0" />
      <geometry>
        <mesh
          filename="package://chimuelo/meshes/front_left_wheel.STL" />
      </geometry>
    </collision>
  </link>
  <joint
    name="front_left_joint"
    type="continuous">
    <origin
      xyz="0 0 0"
      rpy="0 0 0" />
    <parent
      link="support_left_wheel" />
    <child
      link="front_left_wheel" />
    <axis
      xyz="1 0 0" />
  </joint>
  <link
    name="rear_right_link">
    <inertial>
      <origin
        xyz="-0.0139754168097914 0.0543205475500454 9.90235068787371E-05"
        rpy="0 0 0" />
      <mass
        value="0.0537337863904742" />
      <inertia
        ixx="2.52398340856145E-05"
        ixy="-1.65851128010438E-06"
        ixz="9.97793222965961E-08"
        iyy="2.90550894865598E-05"
        iyz="2.03552260410711E-07"
        izz="2.04581561150321E-05" />
    </inertial>
    <visual>
      <origin
        xyz="0 0 0"
        rpy="0 0 0" />
      <geometry>
        <mesh
          filename="package://chimuelo/meshes/rear_right_link.STL" />
      </geometry>
      <material
        name="">
        <color
          rgba="0.250980392156863 0.250980392156863 0.250980392156863 1" />
      </material>
    </visual>
    <collision>
      <origin
        xyz="0 0 0"
        rpy="0 0 0" />
      <geometry>
        <mesh
          filename="package://chimuelo/meshes/rear_right_link.STL" />
      </geometry>
    </collision>
  </link>
  <joint
    name="rear_right_joint1"
    type="continuous">
    <origin
      xyz="-0.12756 -0.076921 -0.14918"
      rpy="1.5688 0.13961 -0.014686" />
    <parent
      link="base_link" />
    <child
      link="rear_right_link" />
    <axis
      xyz="0 -1 0" />
  </joint>
  <link
    name="rear_right_wheel">
    <inertial>
      <origin
        xyz="0.00140350581424464 7.54540874225995E-12 1.17004135716248E-06"
        rpy="0 0 0" />
      <mass
        value="0.205595245521928" />
      <inertia
        ixx="0.000201445693855732"
        ixy="-4.24026610336942E-14"
        ixz="-5.6952908033636E-14"
        iyy="0.000119719345880012"
        iyz="5.35313500630083E-16"
        izz="0.000119717954395117" />
    </inertial>
    <visual>
      <origin
        xyz="0 0 0"
        rpy="0 0 0" />
      <geometry>
        <mesh
          filename="package://chimuelo/meshes/rear_right_wheel.STL" />
      </geometry>
      <material
        name="">
        <color
          rgba="0.792156862745098 0.819607843137255 0.933333333333333 1" />
      </material>
    </visual>
    <collision>
      <origin
        xyz="0 0 0"
        rpy="0 0 0" />
      <geometry>
        <mesh
          filename="package://chimuelo/meshes/rear_right_wheel.STL" />
      </geometry>
    </collision>
  </link>
  <joint
    name="rear_right_joint2"
    type="continuous">
    <origin
      xyz="-0.03659 0.014924 -0.0015141"
      rpy="2.894 -1.5708 0" />
    <parent
      link="rear_right_link" />
    <child
      link="rear_right_wheel" />
    <axis
      xyz="1 0 0" />
  </joint>
  <link
    name="rear_left_link">
    <inertial>
      <origin
        xyz="-0.0139754168097914 0.0543205475500453 9.90235068787371E-05"
        rpy="0 0 0" />
      <mass
        value="0.0537337863904743" />
      <inertia
        ixx="2.52398340856146E-05"
        ixy="-1.65851128010443E-06"
        ixz="9.97793222965384E-08"
        iyy="2.905508948656E-05"
        iyz="2.03552260410693E-07"
        izz="2.04581561150323E-05" />
    </inertial>
    <visual>
      <origin
        xyz="0 0 0"
        rpy="0 0 0" />
      <geometry>
        <mesh
          filename="package://chimuelo/meshes/rear_left_link.STL" />
      </geometry>
      <material
        name="">
        <color
          rgba="0.250980392156863 0.250980392156863 0.250980392156863 1" />
      </material>
    </visual>
    <collision>
      <origin
        xyz="0 0 0"
        rpy="0 0 0" />
      <geometry>
        <mesh
          filename="package://chimuelo/meshes/rear_left_link.STL" />
      </geometry>
    </collision>
  </link>
  <joint
    name="rear_left_joint1"
    type="continuous">
    <origin
      xyz="-0.12756 0.077079 -0.14918"
      rpy="1.5688 0.13961 -0.014686" />
    <parent
      link="base_link" />
    <child
      link="rear_left_link" />
    <axis
      xyz="0 -1 0" />
  </joint>
  <link
    name="rear_left_wheel">
    <inertial>
      <origin
        xyz="0.00140350581424453 7.54529771995749E-12 1.17004135714166E-06"
        rpy="0 0 0" />
      <mass
        value="0.205595245521929" />
      <inertia
        ixx="0.000201445693855732"
        ixy="-4.2402660213131E-14"
        ixz="-5.69528977633615E-14"
        iyy="0.000119719345880012"
        iyz="5.35330513253742E-16"
        izz="0.000119717954395117" />
    </inertial>
    <visual>
      <origin
        xyz="0 0 0"
        rpy="0 0 0" />
      <geometry>
        <mesh
          filename="package://chimuelo/meshes/rear_left_wheel.STL" />
      </geometry>
      <material
        name="">
        <color
          rgba="0.792156862745098 0.819607843137255 0.933333333333333 1" />
      </material>
    </visual>
    <collision>
      <origin
        xyz="0 0 0"
        rpy="0 0 0" />
      <geometry>
        <mesh
          filename="package://chimuelo/meshes/rear_left_wheel.STL" />
      </geometry>
    </collision>
  </link>
  <joint
    name="rear_left_joint2"
    type="continuous">
    <origin
      xyz="-0.03659 0.014924 -0.0015141"
      rpy="2.894 -1.5708 0" />
    <parent
      link="rear_left_link" />
    <child
      link="rear_left_wheel" />
    <axis
      xyz="1 0 0" />
  </joint>
  <link
    name="camerafront_Link">
    <inertial>
      <origin
        xyz="-0.002 4.4409E-16 0"
        rpy="0 0 0" />
      <mass
        value="0.016731" />
      <inertia
        ixx="1.6437E-05"
        ixy="-2.9944E-23"
        ixz="3.3455E-22"
        iyy="2.278E-06"
        iyz="-7.2082E-22"
        izz="1.4204E-05" />
    </inertial>
    <visual>
      <origin
        xyz="0 0 0"
        rpy="0 0 0" />
      <geometry>
        <mesh
          filename="package://chimuelo/meshes/camerafront_Link.STL" />
      </geometry>
      <material
        name="">
        <color
          rgba="0.79216 0.81961 0.93333 0.3" />
      </material>
    </visual>
    <collision>
      <origin
        xyz="0 0 0"
        rpy="0 0 0" />
      <geometry>
        <mesh
          filename="package://chimuelo/meshes/camerafront_Link.STL" />
      </geometry>
    </collision>
  </link>
  <joint
    name="camerafront_joint"
    type="fixed">
    <origin
      xyz="0.21053 7.9351E-05 0.035594"
      rpy="0 0 0" />
    <parent
      link="base_link" />
    <child
      link="camerafront_Link" />
    <axis
      xyz="0 0 0" />
  </joint>
  <link
    name="cameraback_Link">
    <inertial>
      <origin
        xyz="-0.0016341 -2.4731E-06 -0.0011538"
        rpy="0 0 0" />
      <mass
        value="0.011713" />
      <inertia
        ixx="9.0103E-06"
        ixy="-4.9082E-11"
        ixz="4.3103E-07"
        iyy="9.4862E-07"
        iyz="7.7782E-11"
        izz="8.6965E-06" />
    </inertial>
    <visual>
      <origin
        xyz="0 0 0"
        rpy="0 0 0" />
      <geometry>
        <mesh
          filename="package://chimuelo/meshes/cameraback_Link.STL" />
      </geometry>
      <material
        name="">
        <color
          rgba="0.79216 0.81961 0.93333 0.3" />
      </material>
    </visual>
    <collision>
      <origin
        xyz="0 0 0"
        rpy="0 0 0" />
      <geometry>
        <mesh
          filename="package://chimuelo/meshes/cameraback_Link.STL" />
      </geometry>
    </collision>
  </link>
  <joint
    name="cameraback_joint"
    type="fixed">
    <origin
      xyz="-0.24453 0.0020794 0.17412"
      rpy="0 -0.17323 -3.1416" />
    <parent
      link="base_link" />
    <child
      link="cameraback_Link" />
    <axis
      xyz="0 0 0" />
  </joint>
  <link
    name="lidar_Link">
    <inertial>
      <origin
        xyz="-1.86821847256158E-06 0.000176995700032823 -0.0356298866556381"
        rpy="0 0 0" />
      <mass
        value="0.61591423741563" />
      <inertia
        ixx="0.000690610904168957"
        ixy="-2.07889660372515E-10"
        ixz="-3.8206188100131E-08"
        iyy="0.000683786059360278"
        iyz="3.18030533668572E-06"
        izz="0.000839147404934622" />
    </inertial>
    <visual>
      <origin
        xyz="0 0 0"
        rpy="0 0 0" />
      <geometry>
        <mesh
          filename="package://chimuelo/meshes/lidar_Link.STL" />
      </geometry>
      <material
        name="">
        <color
          rgba="0.952941176470588 0.996078431372549 0.694117647058824 1" />
      </material>
    </visual>
    <collision>
      <origin
        xyz="0 0 0"
        rpy="0 0 0" />
      <geometry>
        <mesh
          filename="package://chimuelo/meshes/lidar_Link.STL" />
      </geometry>
    </collision>
  </link>
  <joint
    name="lidar_joint"
    type="fixed">
    <origin
      xyz="0.0024523 0.0019288 0.2346"
      rpy="0 0 0" />
    <parent
      link="base_link" />
    <child
      link="lidar_Link" />
    <axis
      xyz="0 0 0" />
  </joint>
  <link
    name="sup_Link">
    <inertial>
      <origin
        xyz="0.0092271 -0.15 0.013958"
        rpy="0 0 0" />
      <mass
        value="0.43898" />
      <inertia
        ixx="0.0061052"
        ixy="-8.9571E-08"
        ixz="0.0015258"
        iyy="0.0078076"
        iyz="2.3811E-08"
        izz="0.011427" />
    </inertial>
    <visual>
      <origin
        xyz="0 0 0"
        rpy="0 0 0" />
      <geometry>
        <mesh
          filename="package://chimuelo/meshes/sup_Link.STL" />
      </geometry>
      <material
        name="">
        <color
          rgba="1 1 1 0.3" />
      </material>
    </visual>
    <collision>
      <origin
        xyz="0 0 0"
        rpy="0 0 0" />
      <geometry>
        <mesh
          filename="package://chimuelo/meshes/sup_Link.STL" />
      </geometry>
    </collision>
  </link>
  <joint
    name="sup_joint"
    type="fixed">
    <origin
      xyz="0.004191 0.15008 0.18491"
      rpy="0 0 0" />
    <parent
      link="base_link" />
    <child
      link="sup_Link" />
    <axis
      xyz="0 0 0" />
  </joint>
  <link
    name="luces_Link">
    <inertial>
      <origin
        xyz="-0.023886 -6.2177E-07 0.013779"
        rpy="0 0 0" />
      <mass
        value="0.38703" />
      <inertia
        ixx="0.00085878"
        ixy="2.2072E-09"
        ixz="5.4087E-05"
        iyy="0.0003374"
        iyz="-3.4489E-10"
        izz="0.00077205" />
    </inertial>
    <visual>
      <origin
        xyz="0 0 0"
        rpy="0 0 0" />
      <geometry>
        <mesh
          filename="package://chimuelo/meshes/luces_Link.STL" />
      </geometry>
      <material
        name="">
        <color
          rgba="0.79216 0.81961 0.93333 0.3" />
      </material>
    </visual>
    <collision>
      <origin
        xyz="0 0 0"
        rpy="0 0 0" />
      <geometry>
        <mesh
          filename="package://chimuelo/meshes/luces_Link.STL" />
      </geometry>
    </collision>
  </link>
  <joint
    name="luces_joint"
    type="fixed">
    <origin
      xyz="-0.25232 0.0020794 0.13327"
      rpy="0 0.10375 3.1416" />
    <parent
      link="base_link" />
    <child
      link="luces_Link" />
    <axis
      xyz="0 0 0" />
  </joint>
  <link
    name="tapas_Link">
    <inertial>
      <origin
        xyz="-0.203866745404062 0.0199362162738308 -0.00589547774877119"
        rpy="0 0 0" />
      <mass
        value="0.215181361192555" />
      <inertia
        ixx="0.000875785590870731"
        ixy="0.000101217777348423"
        ixz="-1.79141048319832E-08"
        iyy="0.00103679629819384"
        iyz="5.01806058298784E-09"
        izz="0.000536379812696066" />
    </inertial>
    <visual>
      <origin
        xyz="0 0 0"
        rpy="0 0 0" />
      <geometry>
        <mesh
          filename="package://chimuelo/meshes/tapas_Link.STL" />
      </geometry>
      <material
        name="">
        <color
          rgba="1 1 1 1" />
      </material>
    </visual>
    <collision>
      <origin
        xyz="0 0 0"
        rpy="0 0 0" />
      <geometry>
        <mesh
          filename="package://chimuelo/meshes/tapas_Link.STL" />
      </geometry>
    </collision>
  </link>
  <joint
    name="tapas_joint"
    type="fixed">
    <origin
      xyz="0.21153 7.9351E-05 -0.032426"
      rpy="1.5708 0 0" />
    <parent
      link="base_link" />
    <child
      link="tapas_Link" />
    <axis
      xyz="0 0 0" />
  </joint>
  <!-- Camera Back plugin -->
  <gazebo reference="cameraback_Link">
    <sensor type="camera" name="camera_sensor">
      <update_rate>100.0</update_rate>
      <always_on>1</always_on>
      <visualize>true</visualize>

      <camera name="camera">
        <horizontal_fov>1.3962634</horizontal_fov>
        <image>
          <width>640</width>
          <height>480</height>
          <format>R8G8B8</format>
        </image>
        <clip>
          <near>0.02</near>
          <far>320</far>
        </clip>
        <distortion>
          <k1>0.0</k1>
          <k2>0.0</k2>
          <k3>0.0</k3>
          <p1>0.0</p1>
          <p2>0.0</p2>
          <center>0.5 0.5</center>
        </distortion>
      </camera>
      <plugin name="camera_controller" filename="libgazebo_ros_camera.so">
        <ros>
          <namespace>/bocbot</namespace>
          <argument>camera/image_raw:=/bocbot/camera/image</argument>
          <argument>camera/camera_info:=/bocbot/camera/image/cameraback_info</argument>
        </ros>
        <camera_name>cameraback</camera_name>
        <frame_name>cameraback_Link</frame_name>
        <hack_baseline>0.07</hack_baseline>
      </plugin>
    </sensor>
  </gazebo>
  <!-- Camera Front plugin -->
  <gazebo reference="camerafront_Link">
    <sensor type="camera" name="camera_sensor">
      <update_rate>100.0</update_rate>
      <always_on>1</always_on>
      <visualize>true</visualize>

      <camera name="camera">
        <horizontal_fov>1.3962634</horizontal_fov>
        <image>
          <width>640</width>
          <height>480</height>
          <format>R8G8B8</format>
        </image>
        <clip>
          <near>0.02</near>
          <far>320</far>
        </clip>
        <distortion>
          <k1>0.0</k1>
          <k2>0.0</k2>
          <k3>0.0</k3>
          <p1>0.0</p1>
          <p2>0.0</p2>
          <center>0.5 0.5</center>
        </distortion>
      </camera>
      <plugin name="camera_controller" filename="libgazebo_ros_camera.so">
        <ros>
          <namespace>/bocbot</namespace>
          <argument>camera/image_raw:=/bocbot/camera/image</argument>
          <argument>camera/camera_info:=/bocbot/camera/image/camerafront_info</argument>
        </ros>
        <camera_name>camerafront</camera_name>
        <frame_name>camerafront_Link</frame_name>
        <hack_baseline>0.07</hack_baseline>
      </plugin>
    </sensor>
  </gazebo>
  <!-- LiDar plugin -->
  <gazebo reference="lidar_Link">
    <sensor name="lidar" type="gpu_ray">
      <always_on>true</always_on>
      <visualize>false</visualize>
      <update_rate>5</update_rate>
      <ray>
        <scan>
          <horizontal>
            <samples>120</samples>
            <resolution>1.000000</resolution>
            <min_angle>-3.14159</min_angle>
            <max_angle>3.14159</max_angle>
          </horizontal>
          <vertical>
                <samples>120</samples>
                <resolution>1</resolution>
                <min_angle>-${15.0*3.1415926535897931/180.0}</min_angle>
                <max_angle> ${15.0*3.1415926535897931/180.0}</max_angle>
              </vertical>
        </scan>
        <range>
          <min>0.3</min>
          <max>15.0</max>
          <resolution>0.001</resolution>
        </range>
        <noise>
          <type>gaussian</type>
          <mean>0.0</mean>
          <stddev>0.01</stddev>
        </noise>
      </ray>
      <plugin name="gazebo_ros_laser_controller" filename="libgazebo_ros_velodyne_gpu_laser.so">
        
        <ros>
          <remapping>~/out:=scan</remapping>
          
        </ros>
        <output_type>sensor_msgs/LaserScan</output_type>
        <topicName>~/velodyne_points</topicName>
        <frame_name>lidar_Link</frame_name>
      </plugin>
    </sensor>
  </gazebo>
  <gazebo reference="lidar_Link">
    <mu1>0.01</mu1>
    <mu2>0.01</mu2>
    <material>Gazebo/Black</material>
  </gazebo>
  <!-- *********************** WHEEL ODOMETRY ***************************    --> 
  <gazebo>
    <plugin name="two_wheeled_robot_diff_drive" filename="libgazebo_ros_diff_drive.so">

      <update_rate>30</update_rate>
     
      <!-- wheels -->
      <left_joint>front_left_joint</left_joint>
      <right_joint>front_right_joint</right_joint>

      <!-- kinematics -->
      <wheel_separation>0.324523</wheel_separation>
      <wheel_diameter>0.15875</wheel_diameter>

      <!-- limits -->
      <max_wheel_torque>20</max_wheel_torque>
      <max_wheel_acceleration>1.0</max_wheel_acceleration>

      <!-- Receive velocity commands on this ROS topic -->
      <command_topic>cmd_vel</command_topic>

      <!-- output -->
      <!-- When false, publish no wheel odometry data to a ROS topic -->
      <publish_odom>true</publish_odom>

      <!-- When true, publish coordinate transform from odom to base_footprint -->
      <!-- I usually use the robot_localization package to publish this transform -->   
      <publish_odom_tf>false</publish_odom_tf>
    
      <!-- When true, publish coordinate transform from base_link to the wheels -->
      <!-- The robot_state_publisher package is often used to publish this transform -->   
      <publish_wheel_tf>true</publish_wheel_tf>

      <odometry_topic>odom</odometry_topic>
      <odometry_frame>odom</odometry_frame>
      <robot_base_frame>base_link</robot_base_frame>

      <odometry_source>1</odometry_source>
      <ros>
        <remapping>odom:=wheel/odometry</remapping>
      </ros>
    </plugin>
  </gazebo>
</robot>
