<?xml version="1.0" encoding="utf-8"?>
<robot
  name="chimuelo_description">
  <link name="base_footprint">
  </link>
  <joint name="base_joint"    type="fixed">
    <origin xyz="0 0 0.22579" rpy="0 -0.150640 0" />
    <parent link="base_footprint" />
    <child link="base_link" />
  </joint>

  <link
    name="base_link">
    <inertial>
      <origin
        xyz="-0.019376 0.0012573 0.047484"
        rpy="0 0 0" />
      <mass
        value="9.3362" />
      <inertia
        ixx="0.10996"
        ixy="-0.00014648"
        ixz="0.015965"
        iyy="0.1362"
        iyz="0.00018862"
        izz="0.18143" />
    </inertial>
    <visual>
      <origin
        xyz="0 0 0"
        rpy="0 0 0" />
      <geometry>
        <mesh
          filename="package://chimuelo/meshes/base_link.STL" />
      </geometry>
      <material
        name="">
        <color
          rgba="0.69412 0.098039 0.098039 1" />
      </material>
    </visual>
    <collision>
      <origin
        xyz="0 0 0.09255"
        rpy="0 0.150640 0" />
      <geometry>
        <!--mesh
          filename="package://chimuelo/meshes/base_link.STL" /-->
        <box size="0.4806 0.316 0.35323" />
      </geometry>
    </collision>
  </link>
  <link
    name="front_right_wheel">
    <inertial>
      <origin
        xyz="-0.030145 7.2299E-06 -7.774E-07"
        rpy="0 0 0" />
      <mass
        value="0.95802" />
      <inertia
        ixx="0.0027027"
        ixy="3.8106E-07"
        ixz="-4.0985E-08"
        iyy="0.0015854"
        iyz="-3.6463E-09"
        izz="0.0015854" />
    </inertial>
    <visual>
      <origin
        xyz="0 0 0"
        rpy="0 0 3.1416" />
      <geometry>
        <mesh
          filename="package://chimuelo/meshes/front_right_wheel.STL" />
      </geometry>
      <material
        name="">
        <color
          rgba="0.79216 0.81961 0.93333 1" />
      </material>
    </visual>
    <collision>
      <origin
        xyz="0.027 0 0"
        rpy="0 1.5708 0" />
      <geometry>
        <!--mesh
          filename="package://chimuelo/meshes/front_right_wheel.STL" /-->
        <cylinder length="0.054" radius="0.079375" />
      </geometry>
    </collision>
  </link>
  <joint
    name="front_right_joint"
    type="continuous">
    <origin
      xyz="0.15956 -0.22452 -0.14324"
      rpy="0.150640 0 1.5708" />
    <parent
      link="base_link" />
    <child
      link="front_right_wheel" />
    <axis
      xyz="1 0 0" />
  </joint>
  <link
    name="front_left_wheel">
    <inertial>
      <origin
        xyz="0.080855 -3.7512E-06 6.2293E-06"
        rpy="0 0 0" />
      <mass
        value="0.95802" />
      <inertia
        ixx="0.0027027"
        ixy="-1.9771E-07"
        ixz="3.2833E-07"
        iyy="0.0015854"
        iyz="-1.5204E-08"
        izz="0.0015854" />
    </inertial>
    <visual>
      <origin
        xyz="0 0 0"
        rpy="0 0 0" />
      <geometry>
        <mesh
          filename="package://chimuelo/meshes/front_left_wheel.STL" />
      </geometry>
      <material
        name="">
        <color
          rgba="0.79216 0.81961 0.93333 1" />
      </material>
    </visual>
    <collision>
      <origin
        xyz="0.081 0 0"
        rpy="0 1.5708 0" />
      <geometry>
        <!--mesh
          filename="package://chimuelo/meshes/front_left_wheel.STL" /-->
        <cylinder length="0.054" radius="0.079375" />
      </geometry>
    </collision>
  </link>
  <joint
    name="front_left_joint"
    type="continuous">
    <origin
      xyz="0.15956 0.11368 -0.14324"
      rpy="0.150640 0 1.5708" />
    <parent
      link="base_link" />
    <child
      link="front_left_wheel" />
    <axis
      xyz="1 0 0" />
  </joint>
  <link
    name="rear_right_link">
    <inertial>
      <origin
        xyz="-0.013975 0.054321 9.9024E-05"
        rpy="0 0 0" />
      <mass
        value="0.053734" />
      <inertia
        ixx="2.524E-05"
        ixy="-1.6585E-06"
        ixz="9.9779E-08"
        iyy="2.9055E-05"
        iyz="2.0355E-07"
        izz="2.0458E-05" />
    </inertial>
    <visual>
      <origin
        xyz="0 0 0"
        rpy="0 0 0" />
      <geometry>
        <mesh
          filename="package://chimuelo/meshes/rear_right_link.STL" />
      </geometry>
      <material
        name="">
        <color
          rgba="0.25098 0.25098 0.25098 1" />
      </material>
    </visual>
    <collision>
      <origin
        xyz="0 0.07459 0"
        rpy="1.5708 0 0" />
      <geometry>
        <!--mesh
          filename="package://chimuelo/meshes/rear_right_link.STL" /-->
        <box size="0.107 0.086 0.025" />
      </geometry>
    </collision>
  </link>
  <joint
    name="rear_right_joint1"
    type="continuous">
    <origin
      xyz="-0.12756 -0.076921 -0.14918"
      rpy="1.5688 0.13961 -0.014686" />
    <parent
      link="base_link" />
    <child
      link="rear_right_link" />
    <axis
      xyz="0 1 0" />
  </joint>
  <link
    name="rear_right_wheel">
    <inertial>
      <origin
        xyz="0.0014035 7.5454E-12 1.17E-06"
        rpy="0 0 0" />
      <mass
        value="0.2056" />
      <inertia
        ixx="0.00020145"
        ixy="-4.2403E-14"
        ixz="-5.6953E-14"
        iyy="0.00011972"
        iyz="5.3531E-16"
        izz="0.00011972" />
    </inertial>
    <visual>
      <origin
        xyz="0 0 0"
        rpy="0 0 0" />
      <geometry>
        <mesh
          filename="package://chimuelo/meshes/rear_right_wheel.STL" />
      </geometry>
      <material
        name="">
        <color
          rgba="0.79216 0.81961 0.93333 1" />
      </material>
    </visual>
    <collision>
      <origin
        xyz="0 0 0"
        rpy="0 -1.5708 0" />
      <geometry>
        <!--mesh
          filename="package://chimuelo/meshes/rear_right_wheel.STL" /-->
        <cylinder length="0.032" radius="0.045" />
      </geometry>
    </collision>
  </link>
  <joint
    name="rear_right_joint2"
    type="continuous">
    <origin
      xyz="-0.03659 0.014924 -0.0015141"
      rpy="2.894 -1.5708 0" />
    <parent
      link="rear_right_link" />
    <child
      link="rear_right_wheel" />
    <axis
      xyz="1 0 0" />
  </joint>
  <link
    name="rear_left_link">
    <inertial>
      <origin
        xyz="-0.013975 0.054321 9.9024E-05"
        rpy="0 0 0" />
      <mass
        value="0.053734" />
      <inertia
        ixx="2.524E-05"
        ixy="-1.6585E-06"
        ixz="9.9779E-08"
        iyy="2.9055E-05"
        iyz="2.0355E-07"
        izz="2.0458E-05" />
    </inertial>
    <visual>
      <origin
        xyz="0 0 0"
        rpy="0 0 0" />
      <geometry>
        <mesh
          filename="package://chimuelo/meshes/rear_left_link.STL" />
      </geometry>
      <material
        name="">
        <color
          rgba="0.25098 0.25098 0.25098 1" />
      </material>
    </visual>
    <collision>
      <origin
        xyz="0 0.07459 0"
        rpy="1.5708 0 0" />
      <geometry>
        <!--mesh
          filename="package://chimuelo/meshes/rear_left_link.STL" /-->
        <box size="0.107 0.086 0.025" />
      </geometry>
    </collision>
  </link>
  <joint
    name="rear_left_joint1"
    type="continuous">
    <origin
      xyz="-0.12756 0.077079 -0.14918"
      rpy="1.5688 0.13961 -0.014686" />
    <parent
      link="base_link" />
    <child
      link="rear_left_link" />
    <axis
      xyz="0 1 0" />
  </joint>
  <link
    name="rear_left_wheel">
    <inertial>
      <origin
        xyz="0.0014035 7.5453E-12 1.17E-06"
        rpy="0 0 0" />
      <mass
        value="0.2056" />
      <inertia
        ixx="0.00020145"
        ixy="-4.2403E-14"
        ixz="-5.6953E-14"
        iyy="0.00011972"
        iyz="5.3532E-16"
        izz="0.00011972" />
    </inertial>
    <visual>
      <origin
        xyz="0 0 0"
        rpy="0 0 0" />
      <geometry>
        <mesh
          filename="package://chimuelo/meshes/rear_left_wheel.STL" />
      </geometry>
      <material
        name="">
        <color
          rgba="0.79216 0.81961 0.93333 1" />
      </material>
    </visual>
    <collision>
      <origin
        xyz="0 0 0"
        rpy="0 -1.5708 0" />
      <geometry>
        <!--mesh
          filename="package://chimuelo/meshes/rear_left_wheel.STL" /-->
        <cylinder length="0.032" radius="0.045" />
      </geometry>
    </collision>
  </link>
  <joint
    name="rear_left_joint2"
    type="continuous">
    <origin
      xyz="-0.03659 0.014924 -0.0015141"
      rpy="2.894 -1.5708 0" />
    <parent
      link="rear_left_link" />
    <child
      link="rear_left_wheel" />
    <axis
      xyz="1 0 0" />
  </joint>
  <!-- Adding front camera -->
  	<link name="camera_link">
	    <collision>
		      <origin xyz="0 0 0" rpy="0 0 0"/>
		      <geometry>
			    <box size="0.05 0.05 0.05"/>
		      </geometry>
	    </collision>
	    <visual>
		      <origin xyz="0 0 0" rpy="0 0 0"/>
		      <geometry>
			    <box size="0.05 0.05 0.05"/>
		      </geometry>
	    </visual>
	    <inertial>
		      <mass value="1e-5" />
		      <origin xyz="0 0 0" rpy="0 0 0"/>
		      <inertia ixx="1e-6" ixy="0" ixz="0" iyy="1e-6" iyz="0" izz="1e-6" />
	    </inertial>
	</link>

	<joint name="camera_joint" type="fixed">
	    <axis xyz="0 0 1" />
	    <origin xyz="0 0 0.6" rpy="0 0 0"/>
	    <parent link="base_footprint"/>
	    <child link="camera_link"/>
	</joint>
	
  	
	
		<!-- Camera plugin -->
  <gazebo reference="camera_link">
    <sensor type="camera" name="camera_sensor">
      <update_rate>100.0</update_rate>
      <always_on>1</always_on>
      <visualize>true</visualize>

      <camera name="camera">
        <horizontal_fov>1.3962634</horizontal_fov>
        <image>
          <width>640</width>
          <height>480</height>
          <format>R8G8B8</format>
        </image>
        <clip>
          <near>0.02</near>
          <far>320</far>
        </clip>
        <distortion>
          <k1>0.0</k1>
          <k2>0.0</k2>
          <k3>0.0</k3>
          <p1>0.0</p1>
          <p2>0.0</p2>
          <center>0.5 0.5</center>
        </distortion>
      </camera>
      <plugin name="camera_controller" filename="libgazebo_ros_camera.so">
        <ros>
          <namespace>/bocbot</namespace>
          <argument>camera/image_raw:=/bocbot/camera/image</argument>
          <argument>camera/camera_info:=/bocbot/camera/image/camera_info</argument>
        </ros>
        <camera_name>camera</camera_name>
        <frame_name>camera_link</frame_name>
        <hack_baseline>0.07</hack_baseline>
      </plugin>
    </sensor>
  </gazebo>
  
  <!-- LiDar plugin -->
  <gazebo reference="camera_link">
    <sensor name="lidar" type="gpu_ray">
      <always_on>true</always_on>
      <visualize>false</visualize>
      <update_rate>5</update_rate>
      <ray>
        <scan>
          <horizontal>
            <samples>120</samples>
            <resolution>1.000000</resolution>
            <min_angle>-3.14159</min_angle>
            <max_angle>3.14159</max_angle>
          </horizontal>
          <vertical>
                <samples>120</samples>
                <resolution>1</resolution>
                <min_angle>-${15.0*3.1415926535897931/180.0}</min_angle>
                <max_angle> ${15.0*3.1415926535897931/180.0}</max_angle>
              </vertical>
        </scan>
        <range>
          <min>0.3</min>
          <max>15.0</max>
          <resolution>0.001</resolution>
        </range>
        <noise>
          <type>gaussian</type>
          <mean>0.0</mean>
          <stddev>0.01</stddev>
        </noise>
      </ray>
      <plugin name="gazebo_ros_laser_controller" filename="libgazebo_ros_velodyne_gpu_laser.so">
        
        <ros>
          <remapping>~/out:=scan</remapping>
          
        </ros>
        <output_type>sensor_msgs/LaserScan</output_type>
        <topicName>~/velodyne_points</topicName>
        <frame_name>camera_link</frame_name>
      </plugin>
    </sensor>
  </gazebo>
  <gazebo reference="camera_link">
    <mu1>0.01</mu1>
    <mu2>0.01</mu2>
    <material>Gazebo/Black</material>
  </gazebo>
  <!-- *********************** WHEEL ODOMETRY ***************************    --> 
  <gazebo>
    <plugin name="two_wheeled_robot_diff_drive" filename="libgazebo_ros_diff_drive.so">

      <update_rate>30</update_rate>
     
      <!-- wheels -->
      <left_joint>front_left_joint</left_joint>
      <right_joint>front_right_joint</right_joint>

      <!-- kinematics -->
      <wheel_separation>0.33820</wheel_separation>
      <wheel_diameter>0.15875</wheel_diameter>

      <!-- limits -->
      <max_wheel_torque>20</max_wheel_torque>
      <max_wheel_acceleration>1.0</max_wheel_acceleration>

      <!-- Receive velocity commands on this ROS topic -->
      <command_topic>cmd_vel</command_topic>

      <!-- output -->
      <!-- When false, publish no wheel odometry data to a ROS topic -->
      <publish_odom>true</publish_odom>

      <!-- When true, publish coordinate transform from odom to base_footprint -->
      <!-- I usually use the robot_localization package to publish this transform -->   
      <publish_odom_tf>false</publish_odom_tf>
    
      <!-- When true, publish coordinate transform from base_link to the wheels -->
      <!-- The robot_state_publisher package is often used to publish this transform -->   
      <publish_wheel_tf>true</publish_wheel_tf>

      <odometry_topic>odom</odometry_topic>
      <odometry_frame>odom</odometry_frame>
      <robot_base_frame>base_link</robot_base_frame>

      <odometry_source>1</odometry_source>
      <ros>
        <remapping>odom:=wheel/odometry</remapping>
      </ros>
    </plugin>
  </gazebo>
  
  
</robot>
